
Running tests...
----------------------------------------------------------------------
F...F
======================================================================
FAIL [0.014s]: test2 (helloworld_tests.HelloWorldTest)
----------------------------------------------------------------------
Traceback (most recent call last):
  File "/usr/lib/python3.10/unittest/case.py", line 59, in testPartExecutor
    yield
  File "/usr/lib/python3.10/unittest/case.py", line 591, in run
    self._callTestMethod(testMethod)
  File "/usr/lib/python3.10/unittest/case.py", line 549, in _callTestMethod
    method()
  File "/media/Datacenter/google/education/torrens/DOT/DOT/src/unittest/python/helloworld_tests.py", line 15, in test2
    verify(out).write("Hello world of Monty Python\n")
  File "/usr/lib/python3/dist-packages/mockito/invocation.py", line 242, in __call__
    self.verification.verify(self, len(matched_invocations))
  File "/usr/lib/python3/dist-packages/mockito/verification.py", line 93, in verify
    raise VerificationError(
mockito.verification.VerificationError: 
Wanted but not invoked:

    write('Hello world of Monty Python\n')

Instead got:

    write('Hello world of Python\n')



======================================================================
FAIL [0.004s]: test_upper (helloworld_tests.HelloWorldTest)
----------------------------------------------------------------------
Traceback (most recent call last):
  File "/usr/lib/python3.10/unittest/case.py", line 59, in testPartExecutor
    yield
  File "/usr/lib/python3.10/unittest/case.py", line 591, in run
    self._callTestMethod(testMethod)
  File "/usr/lib/python3.10/unittest/case.py", line 549, in _callTestMethod
    method()
  File "/media/Datacenter/google/education/torrens/DOT/DOT/src/unittest/python/helloworld_tests.py", line 18, in test_upper
    self.assertEqual('foo'.upper(), 'FOo')
  File "/usr/lib/python3.10/unittest/case.py", line 845, in assertEqual
    assertion_func(first, second, msg=msg)
  File "/usr/lib/python3.10/unittest/case.py", line 1226, in assertMultiLineEqual
    self.fail(self._formatMessage(msg, standardMsg))
  File "/usr/lib/python3.10/unittest/case.py", line 675, in fail
    raise self.failureException(msg)
AssertionError: 'FOO' != 'FOo'
- FOO
?   ^
+ FOo
?   ^


----------------------------------------------------------------------
Ran 5 tests in 0.083s

FAILED (failures=2)

Generating XML reports...
